2020-06-23 06:07:51,925 INFO: Microblog Startup [in C:\Users\ajshe\microblog2\app\__init__.py:77]
2020-06-23 06:08:19,240 INFO: Microblog Startup [in C:\Users\ajshe\microblog2\app\__init__.py:77]
2020-06-23 06:10:09,481 INFO: Microblog Startup [in C:\Users\ajshe\microblog2\app\__init__.py:77]
2020-06-23 06:10:27,527 INFO: Microblog Startup [in C:\Users\ajshe\microblog2\app\__init__.py:77]
2020-06-23 06:10:54,159 INFO: Microblog Startup [in C:\Users\ajshe\microblog2\app\__init__.py:77]
2020-06-23 06:11:30,101 INFO: Microblog Startup [in C:\Users\ajshe\microblog2\app\__init__.py:77]
2020-06-23 06:12:13,588 INFO: Microblog Startup [in C:\Users\ajshe\microblog2\app\__init__.py:77]
2020-06-23 06:12:47,800 INFO: Microblog Startup [in C:\Users\ajshe\microblog2\app\__init__.py:77]
2020-06-23 06:13:16,081 INFO: Microblog Startup [in C:\Users\ajshe\microblog2\app\__init__.py:77]
2020-06-23 06:13:37,792 INFO: Microblog Startup [in C:\Users\ajshe\microblog2\app\__init__.py:77]
2020-06-23 06:13:56,998 INFO: Microblog Startup [in C:\Users\ajshe\microblog2\app\__init__.py:77]
2020-06-23 06:14:10,524 INFO: Microblog Startup [in C:\Users\ajshe\microblog2\app\__init__.py:77]
2020-06-23 06:19:06,576 INFO: Microblog Startup [in C:\Users\ajshe\microblog2\app\__init__.py:77]
2020-06-23 06:19:17,581 INFO: Microblog Startup [in C:\Users\ajshe\microblog2\app\__init__.py:77]
2020-06-23 06:19:50,194 INFO: Microblog Startup [in C:\Users\ajshe\microblog2\app\__init__.py:77]
2020-06-23 06:20:03,763 INFO: Microblog Startup [in C:\Users\ajshe\microblog2\app\__init__.py:77]
2020-06-23 06:22:04,207 INFO: Microblog Startup [in C:\Users\ajshe\microblog2\app\__init__.py:77]
2020-06-23 06:22:14,877 INFO: Microblog Startup [in C:\Users\ajshe\microblog2\app\__init__.py:77]
2020-06-23 06:45:25,892 INFO: Microblog Startup [in C:\Users\ajshe\microblog2\app\__init__.py:77]
2020-06-23 16:00:12,747 INFO: Microblog Startup [in C:\Users\ajshe\microblog2\app\__init__.py:77]
2020-06-23 16:14:39,544 ERROR: Exception on /api/users [GET] [in c:\users\ajshe\microblog2\venv\lib\site-packages\flask\app.py:1891]
Traceback (most recent call last):
  File "c:\users\ajshe\microblog2\venv\lib\site-packages\flask\app.py", line 2447, in wsgi_app
    response = self.full_dispatch_request()
  File "c:\users\ajshe\microblog2\venv\lib\site-packages\flask\app.py", line 1953, in full_dispatch_request
    return self.finalize_request(rv)
  File "c:\users\ajshe\microblog2\venv\lib\site-packages\flask\app.py", line 1968, in finalize_request
    response = self.make_response(rv)
  File "c:\users\ajshe\microblog2\venv\lib\site-packages\flask\app.py", line 2097, in make_response
    raise TypeError(
TypeError: The view function did not return a valid response. The function either returned None or ended without a return statement.
2020-06-23 16:17:00,607 ERROR: Exception on /api/users [GET] [in c:\users\ajshe\microblog2\venv\lib\site-packages\flask\app.py:1891]
Traceback (most recent call last):
  File "c:\users\ajshe\microblog2\venv\lib\site-packages\flask\app.py", line 2447, in wsgi_app
    response = self.full_dispatch_request()
  File "c:\users\ajshe\microblog2\venv\lib\site-packages\flask\app.py", line 1953, in full_dispatch_request
    return self.finalize_request(rv)
  File "c:\users\ajshe\microblog2\venv\lib\site-packages\flask\app.py", line 1968, in finalize_request
    response = self.make_response(rv)
  File "c:\users\ajshe\microblog2\venv\lib\site-packages\flask\app.py", line 2097, in make_response
    raise TypeError(
TypeError: The view function did not return a valid response. The function either returned None or ended without a return statement.
2020-06-23 16:21:37,597 INFO: Microblog Startup [in C:\Users\ajshe\microblog2\app\__init__.py:77]
2020-06-23 16:44:15,975 INFO: Microblog Startup [in C:\Users\ajshe\microblog2\app\__init__.py:77]
2020-06-23 19:35:29,271 INFO: Microblog Startup [in C:\Users\ajshe\microblog2\app\__init__.py:77]
2020-06-23 19:35:37,625 ERROR: Exception on /api/users [POST] [in c:\users\ajshe\microblog2\venv\lib\site-packages\flask\app.py:1891]
Traceback (most recent call last):
  File "c:\users\ajshe\microblog2\venv\lib\site-packages\flask\app.py", line 2447, in wsgi_app
    response = self.full_dispatch_request()
  File "c:\users\ajshe\microblog2\venv\lib\site-packages\flask\app.py", line 1952, in full_dispatch_request
    rv = self.handle_user_exception(e)
  File "c:\users\ajshe\microblog2\venv\lib\site-packages\flask\app.py", line 1821, in handle_user_exception
    reraise(exc_type, exc_value, tb)
  File "c:\users\ajshe\microblog2\venv\lib\site-packages\flask\_compat.py", line 39, in reraise
    raise value
  File "c:\users\ajshe\microblog2\venv\lib\site-packages\flask\app.py", line 1950, in full_dispatch_request
    rv = self.dispatch_request()
  File "c:\users\ajshe\microblog2\venv\lib\site-packages\flask\app.py", line 1936, in dispatch_request
    return self.view_functions[rule.endpoint](**req.view_args)
  File "C:\Users\ajshe\microblog2\app\api\users.py", line 46, in create_user
    user.from_dict(data, new_user=True)
TypeError: from_dict() got multiple values for argument 'new_user'
2020-06-23 19:36:32,307 INFO: Microblog Startup [in C:\Users\ajshe\microblog2\app\__init__.py:77]
2020-06-23 19:36:35,696 ERROR: Exception on /api/users [POST] [in c:\users\ajshe\microblog2\venv\lib\site-packages\flask\app.py:1891]
Traceback (most recent call last):
  File "c:\users\ajshe\microblog2\venv\lib\site-packages\flask\app.py", line 2447, in wsgi_app
    response = self.full_dispatch_request()
  File "c:\users\ajshe\microblog2\venv\lib\site-packages\flask\app.py", line 1952, in full_dispatch_request
    rv = self.handle_user_exception(e)
  File "c:\users\ajshe\microblog2\venv\lib\site-packages\flask\app.py", line 1821, in handle_user_exception
    reraise(exc_type, exc_value, tb)
  File "c:\users\ajshe\microblog2\venv\lib\site-packages\flask\_compat.py", line 39, in reraise
    raise value
  File "c:\users\ajshe\microblog2\venv\lib\site-packages\flask\app.py", line 1950, in full_dispatch_request
    rv = self.dispatch_request()
  File "c:\users\ajshe\microblog2\venv\lib\site-packages\flask\app.py", line 1936, in dispatch_request
    return self.view_functions[rule.endpoint](**req.view_args)
  File "C:\Users\ajshe\microblog2\app\api\users.py", line 46, in create_user
    user.from_dict(data, new_user=True)
TypeError: from_dict() got multiple values for argument 'new_user'
2020-06-23 19:36:42,122 ERROR: Exception on /api/users [POST] [in c:\users\ajshe\microblog2\venv\lib\site-packages\flask\app.py:1891]
Traceback (most recent call last):
  File "c:\users\ajshe\microblog2\venv\lib\site-packages\flask\app.py", line 2447, in wsgi_app
    response = self.full_dispatch_request()
  File "c:\users\ajshe\microblog2\venv\lib\site-packages\flask\app.py", line 1952, in full_dispatch_request
    rv = self.handle_user_exception(e)
  File "c:\users\ajshe\microblog2\venv\lib\site-packages\flask\app.py", line 1821, in handle_user_exception
    reraise(exc_type, exc_value, tb)
  File "c:\users\ajshe\microblog2\venv\lib\site-packages\flask\_compat.py", line 39, in reraise
    raise value
  File "c:\users\ajshe\microblog2\venv\lib\site-packages\flask\app.py", line 1950, in full_dispatch_request
    rv = self.dispatch_request()
  File "c:\users\ajshe\microblog2\venv\lib\site-packages\flask\app.py", line 1936, in dispatch_request
    return self.view_functions[rule.endpoint](**req.view_args)
  File "C:\Users\ajshe\microblog2\app\api\users.py", line 46, in create_user
    user.from_dict(data, new_user=True)
TypeError: from_dict() got multiple values for argument 'new_user'
2020-06-23 19:39:05,716 ERROR: Exception on /api/users [POST] [in c:\users\ajshe\microblog2\venv\lib\site-packages\flask\app.py:1891]
Traceback (most recent call last):
  File "c:\users\ajshe\microblog2\venv\lib\site-packages\flask\app.py", line 2447, in wsgi_app
    response = self.full_dispatch_request()
  File "c:\users\ajshe\microblog2\venv\lib\site-packages\flask\app.py", line 1952, in full_dispatch_request
    rv = self.handle_user_exception(e)
  File "c:\users\ajshe\microblog2\venv\lib\site-packages\flask\app.py", line 1821, in handle_user_exception
    reraise(exc_type, exc_value, tb)
  File "c:\users\ajshe\microblog2\venv\lib\site-packages\flask\_compat.py", line 39, in reraise
    raise value
  File "c:\users\ajshe\microblog2\venv\lib\site-packages\flask\app.py", line 1950, in full_dispatch_request
    rv = self.dispatch_request()
  File "c:\users\ajshe\microblog2\venv\lib\site-packages\flask\app.py", line 1936, in dispatch_request
    return self.view_functions[rule.endpoint](**req.view_args)
  File "C:\Users\ajshe\microblog2\app\api\users.py", line 40, in create_user
    return bad_request('must include username, email and password fields')
  File "C:\Users\ajshe\microblog2\app\api\errors.py", line 13, in bad_request
    return error_response(400, message)
  File "C:\Users\ajshe\microblog2\app\api\errors.py", line 5, in error_response
    payload = {'error': HTTP_STATUS_CODES.get(status_Code, 'Uknown error')}
NameError: name 'status_Code' is not defined
2020-06-23 19:40:35,564 INFO: Microblog Startup [in C:\Users\ajshe\microblog2\app\__init__.py:77]
