2020-06-06 01:38:07,015 ERROR: Exception on /all_users [GET] [in c:\users\ajshe\microblog2\venv\lib\site-packages\flask\app.py:1891]
Traceback (most recent call last):
  File "c:\users\ajshe\microblog2\venv\lib\site-packages\flask\app.py", line 2447, in wsgi_app
    response = self.full_dispatch_request()
  File "c:\users\ajshe\microblog2\venv\lib\site-packages\flask\app.py", line 1952, in full_dispatch_request
    rv = self.handle_user_exception(e)
  File "c:\users\ajshe\microblog2\venv\lib\site-packages\flask\app.py", line 1821, in handle_user_exception
    reraise(exc_type, exc_value, tb)
  File "c:\users\ajshe\microblog2\venv\lib\site-packages\flask\_compat.py", line 39, in reraise
    raise value
  File "c:\users\ajshe\microblog2\venv\lib\site-packages\flask\app.py", line 1950, in full_dispatch_request
    rv = self.dispatch_request()
  File "c:\users\ajshe\microblog2\venv\lib\site-packages\flask\app.py", line 1936, in dispatch_request
    return self.view_functions[rule.endpoint](**req.view_args)
  File "c:\users\ajshe\microblog2\venv\lib\site-packages\flask_login\utils.py", line 272, in decorated_view
    return func(*args, **kwargs)
  File "C:\Users\ajshe\microblog2\app\main\routes.py", line 42, in all_users
    return render_template('all_users.html', title = _('All Users'), users=users.items, next_url=next_url, prev_url=prev_url)
  File "c:\users\ajshe\microblog2\venv\lib\site-packages\flask\templating.py", line 138, in render_template
    ctx.app.jinja_env.get_or_select_template(template_name_or_list),
  File "c:\users\ajshe\microblog2\venv\lib\site-packages\jinja2\environment.py", line 930, in get_or_select_template
    return self.get_template(template_name_or_list, parent, globals)
  File "c:\users\ajshe\microblog2\venv\lib\site-packages\jinja2\environment.py", line 883, in get_template
    return self._load_template(name, self.make_globals(globals))
  File "c:\users\ajshe\microblog2\venv\lib\site-packages\jinja2\environment.py", line 857, in _load_template
    template = self.loader.load(self, name, globals)
  File "c:\users\ajshe\microblog2\venv\lib\site-packages\jinja2\loaders.py", line 127, in load
    code = environment.compile(source, name, filename)
  File "c:\users\ajshe\microblog2\venv\lib\site-packages\jinja2\environment.py", line 638, in compile
    self.handle_exception(source=source_hint)
  File "c:\users\ajshe\microblog2\venv\lib\site-packages\jinja2\environment.py", line 832, in handle_exception
    reraise(*rewrite_traceback_stack(source=source))
  File "c:\users\ajshe\microblog2\venv\lib\site-packages\jinja2\_compat.py", line 28, in reraise
    raise value.with_traceback(tb)
  File "C:\Users\ajshe\microblog2\app\templates\all_users.html", line 33, in template
    {% endif %}
jinja2.exceptions.TemplateSyntaxError: Encountered unknown tag 'endif'. Jinja was looking for the following tags: 'endfor' or 'else'. The innermost block that needs to be closed is 'for'.
2020-06-06 01:38:26,222 INFO: Microblog Startup [in C:\Users\ajshe\microblog2\app\__init__.py:74]
2020-06-06 01:38:27,980 ERROR: Exception on /all_users [GET] [in c:\users\ajshe\microblog2\venv\lib\site-packages\flask\app.py:1891]
Traceback (most recent call last):
  File "c:\users\ajshe\microblog2\venv\lib\site-packages\flask\app.py", line 2447, in wsgi_app
    response = self.full_dispatch_request()
  File "c:\users\ajshe\microblog2\venv\lib\site-packages\flask\app.py", line 1952, in full_dispatch_request
    rv = self.handle_user_exception(e)
  File "c:\users\ajshe\microblog2\venv\lib\site-packages\flask\app.py", line 1821, in handle_user_exception
    reraise(exc_type, exc_value, tb)
  File "c:\users\ajshe\microblog2\venv\lib\site-packages\flask\_compat.py", line 39, in reraise
    raise value
  File "c:\users\ajshe\microblog2\venv\lib\site-packages\flask\app.py", line 1950, in full_dispatch_request
    rv = self.dispatch_request()
  File "c:\users\ajshe\microblog2\venv\lib\site-packages\flask\app.py", line 1936, in dispatch_request
    return self.view_functions[rule.endpoint](**req.view_args)
  File "c:\users\ajshe\microblog2\venv\lib\site-packages\flask_login\utils.py", line 272, in decorated_view
    return func(*args, **kwargs)
  File "C:\Users\ajshe\microblog2\app\main\routes.py", line 42, in all_users
    return render_template('all_users.html', title = _('All Users'), users=users.items, next_url=next_url, prev_url=prev_url)
  File "c:\users\ajshe\microblog2\venv\lib\site-packages\flask\templating.py", line 138, in render_template
    ctx.app.jinja_env.get_or_select_template(template_name_or_list),
  File "c:\users\ajshe\microblog2\venv\lib\site-packages\jinja2\environment.py", line 930, in get_or_select_template
    return self.get_template(template_name_or_list, parent, globals)
  File "c:\users\ajshe\microblog2\venv\lib\site-packages\jinja2\environment.py", line 883, in get_template
    return self._load_template(name, self.make_globals(globals))
  File "c:\users\ajshe\microblog2\venv\lib\site-packages\jinja2\environment.py", line 857, in _load_template
    template = self.loader.load(self, name, globals)
  File "c:\users\ajshe\microblog2\venv\lib\site-packages\jinja2\loaders.py", line 127, in load
    code = environment.compile(source, name, filename)
  File "c:\users\ajshe\microblog2\venv\lib\site-packages\jinja2\environment.py", line 638, in compile
    self.handle_exception(source=source_hint)
  File "c:\users\ajshe\microblog2\venv\lib\site-packages\jinja2\environment.py", line 832, in handle_exception
    reraise(*rewrite_traceback_stack(source=source))
  File "c:\users\ajshe\microblog2\venv\lib\site-packages\jinja2\_compat.py", line 28, in reraise
    raise value.with_traceback(tb)
  File "C:\Users\ajshe\microblog2\app\templates\all_users.html", line 35, in template
    {% endfor %}
jinja2.exceptions.TemplateSyntaxError: Encountered unknown tag 'endfor'. You probably made a nesting mistake. Jinja is expecting this tag, but currently looking for 'elif' or 'else' or 'endif'. The innermost block that needs to be closed is 'if'.
2020-06-06 01:41:16,787 INFO: Microblog Startup [in C:\Users\ajshe\microblog2\app\__init__.py:74]
2020-06-06 01:41:18,382 ERROR: Exception on /all_users [GET] [in c:\users\ajshe\microblog2\venv\lib\site-packages\flask\app.py:1891]
Traceback (most recent call last):
  File "c:\users\ajshe\microblog2\venv\lib\site-packages\flask\app.py", line 2447, in wsgi_app
    response = self.full_dispatch_request()
  File "c:\users\ajshe\microblog2\venv\lib\site-packages\flask\app.py", line 1952, in full_dispatch_request
    rv = self.handle_user_exception(e)
  File "c:\users\ajshe\microblog2\venv\lib\site-packages\flask\app.py", line 1821, in handle_user_exception
    reraise(exc_type, exc_value, tb)
  File "c:\users\ajshe\microblog2\venv\lib\site-packages\flask\_compat.py", line 39, in reraise
    raise value
  File "c:\users\ajshe\microblog2\venv\lib\site-packages\flask\app.py", line 1950, in full_dispatch_request
    rv = self.dispatch_request()
  File "c:\users\ajshe\microblog2\venv\lib\site-packages\flask\app.py", line 1936, in dispatch_request
    return self.view_functions[rule.endpoint](**req.view_args)
  File "c:\users\ajshe\microblog2\venv\lib\site-packages\flask_login\utils.py", line 272, in decorated_view
    return func(*args, **kwargs)
  File "C:\Users\ajshe\microblog2\app\main\routes.py", line 42, in all_users
    return render_template('all_users.html', title = _('All Users'), users=users.items, next_url=next_url, prev_url=prev_url)
  File "c:\users\ajshe\microblog2\venv\lib\site-packages\flask\templating.py", line 138, in render_template
    ctx.app.jinja_env.get_or_select_template(template_name_or_list),
  File "c:\users\ajshe\microblog2\venv\lib\site-packages\jinja2\environment.py", line 930, in get_or_select_template
    return self.get_template(template_name_or_list, parent, globals)
  File "c:\users\ajshe\microblog2\venv\lib\site-packages\jinja2\environment.py", line 883, in get_template
    return self._load_template(name, self.make_globals(globals))
  File "c:\users\ajshe\microblog2\venv\lib\site-packages\jinja2\environment.py", line 857, in _load_template
    template = self.loader.load(self, name, globals)
  File "c:\users\ajshe\microblog2\venv\lib\site-packages\jinja2\loaders.py", line 127, in load
    code = environment.compile(source, name, filename)
  File "c:\users\ajshe\microblog2\venv\lib\site-packages\jinja2\environment.py", line 638, in compile
    self.handle_exception(source=source_hint)
  File "c:\users\ajshe\microblog2\venv\lib\site-packages\jinja2\environment.py", line 832, in handle_exception
    reraise(*rewrite_traceback_stack(source=source))
  File "c:\users\ajshe\microblog2\venv\lib\site-packages\jinja2\_compat.py", line 28, in reraise
    raise value.with_traceback(tb)
  File "C:\Users\ajshe\microblog2\app\templates\all_users.html", line 25, in template
    {% if user.about_me is not None %}
jinja2.exceptions.TemplateAssertionError: no test named 'None'
2020-06-06 01:41:39,568 INFO: Microblog Startup [in C:\Users\ajshe\microblog2\app\__init__.py:74]
2020-06-06 01:42:32,272 INFO: Microblog Startup [in C:\Users\ajshe\microblog2\app\__init__.py:74]
2020-06-06 01:42:58,971 INFO: Microblog Startup [in C:\Users\ajshe\microblog2\app\__init__.py:74]
2020-06-06 01:43:29,184 INFO: Microblog Startup [in C:\Users\ajshe\microblog2\app\__init__.py:74]
2020-06-06 01:46:07,229 INFO: Microblog Startup [in C:\Users\ajshe\microblog2\app\__init__.py:74]
2020-06-06 01:46:53,762 INFO: Microblog Startup [in C:\Users\ajshe\microblog2\app\__init__.py:74]
2020-06-06 01:48:49,358 INFO: Microblog Startup [in C:\Users\ajshe\microblog2\app\__init__.py:74]
2020-06-06 01:50:07,773 INFO: Microblog Startup [in C:\Users\ajshe\microblog2\app\__init__.py:74]
2020-06-06 01:50:24,384 INFO: Microblog Startup [in C:\Users\ajshe\microblog2\app\__init__.py:74]
2020-06-06 02:21:59,169 INFO: Microblog Startup [in C:\Users\ajshe\microblog2\app\__init__.py:74]
